Traceback (most recent call last):
  File "/Users/pconline/workspace/python/web/ocr/ocr_service/settings.py", line 132, in getSession
    with tf.gfile.FastGFile(cf.get("graph_path"), 'rb') as f:
NameError: name 'cf' is not defined

During handling of the above exception, another exception occurred:

Traceback (most recent call last):
  File "manage.py", line 21, in <module>
    main()
  File "manage.py", line 17, in main
    execute_from_command_line(sys.argv)
  File "/Users/pconline/anaconda3/envs/tensorflow12/lib/python3.6/site-packages/django/core/management/__init__.py", line 381, in execute_from_command_line
    utility.execute()
  File "/Users/pconline/anaconda3/envs/tensorflow12/lib/python3.6/site-packages/django/core/management/__init__.py", line 325, in execute
    settings.INSTALLED_APPS
  File "/Users/pconline/anaconda3/envs/tensorflow12/lib/python3.6/site-packages/django/conf/__init__.py", line 79, in __getattr__
    self._setup(name)
  File "/Users/pconline/anaconda3/envs/tensorflow12/lib/python3.6/site-packages/django/conf/__init__.py", line 66, in _setup
    self._wrapped = Settings(settings_module)
  File "/Users/pconline/anaconda3/envs/tensorflow12/lib/python3.6/site-packages/django/conf/__init__.py", line 157, in __init__
    mod = importlib.import_module(self.SETTINGS_MODULE)
  File "/Users/pconline/anaconda3/envs/tensorflow12/lib/python3.6/importlib/__init__.py", line 126, in import_module
    return _bootstrap._gcd_import(name[level:], package, level)
  File "<frozen importlib._bootstrap>", line 994, in _gcd_import
  File "<frozen importlib._bootstrap>", line 971, in _find_and_load
  File "<frozen importlib._bootstrap>", line 955, in _find_and_load_unlocked
  File "<frozen importlib._bootstrap>", line 665, in _load_unlocked
  File "<frozen importlib._bootstrap_external>", line 678, in exec_module
  File "<frozen importlib._bootstrap>", line 219, in _call_with_frames_removed
  File "/Users/pconline/workspace/python/web/ocr/ocr_service/settings.py", line 152, in <module>
    "sess": getSession(), #载入模型
  File "/Users/pconline/workspace/python/web/ocr/ocr_service/settings.py", line 146, in getSession
    print("Unexpected error:", sys.exc_info())
NameError: name 'sys' is not defined
Traceback (most recent call last):
  File "/Users/pconline/workspace/python/web/ocr/ocr_service/settings.py", line 132, in getSession
    with tf.gfile.FastGFile(cf.get("graph_path"), 'rb') as f:
NameError: name 'cf' is not defined

During handling of the above exception, another exception occurred:

Traceback (most recent call last):
  File "manage.py", line 21, in <module>
    main()
  File "manage.py", line 17, in main
    execute_from_command_line(sys.argv)
  File "/Users/pconline/anaconda3/envs/tensorflow12/lib/python3.6/site-packages/django/core/management/__init__.py", line 381, in execute_from_command_line
    utility.execute()
  File "/Users/pconline/anaconda3/envs/tensorflow12/lib/python3.6/site-packages/django/core/management/__init__.py", line 325, in execute
    settings.INSTALLED_APPS
  File "/Users/pconline/anaconda3/envs/tensorflow12/lib/python3.6/site-packages/django/conf/__init__.py", line 79, in __getattr__
    self._setup(name)
  File "/Users/pconline/anaconda3/envs/tensorflow12/lib/python3.6/site-packages/django/conf/__init__.py", line 66, in _setup
    self._wrapped = Settings(settings_module)
  File "/Users/pconline/anaconda3/envs/tensorflow12/lib/python3.6/site-packages/django/conf/__init__.py", line 157, in __init__
    mod = importlib.import_module(self.SETTINGS_MODULE)
  File "/Users/pconline/anaconda3/envs/tensorflow12/lib/python3.6/importlib/__init__.py", line 126, in import_module
    return _bootstrap._gcd_import(name[level:], package, level)
  File "<frozen importlib._bootstrap>", line 994, in _gcd_import
  File "<frozen importlib._bootstrap>", line 971, in _find_and_load
  File "<frozen importlib._bootstrap>", line 955, in _find_and_load_unlocked
  File "<frozen importlib._bootstrap>", line 665, in _load_unlocked
  File "<frozen importlib._bootstrap_external>", line 678, in exec_module
  File "<frozen importlib._bootstrap>", line 219, in _call_with_frames_removed
  File "/Users/pconline/workspace/python/web/ocr/ocr_service/settings.py", line 152, in <module>
    "sess": getSession(), #载入模型
  File "/Users/pconline/workspace/python/web/ocr/ocr_service/settings.py", line 146, in getSession
    print("Unexpected error:", sys.exc_info())
NameError: name 'sys' is not defined
